# 4 Лабораторная работа Python. 4-й вариант.
## Замыкание, отбирающее только уникальные значения из переданных.
![изображение](https://github.com/Hasper1337/4laba/assets/145243810/71696961-71b1-4cfb-b75b-87476364ea85)

`unique_values` - это внешняя функция, которая создает и возвращает внутреннюю функцию `add`. Внутренняя функция `add` имеет доступ к переменной `seen` из своего внешнего области видимости. Каждый раз, когда вы вызываете функцию `add`, она проверяет, было ли значение уже добавлено в `seen`, и если нет, добавляет его и возвращает `True`. Если значение уже было добавлено, она возвращает `False`.

В выводе ответа создаем список `unique_values_list` в который записывем уникальные значения полученные из `random.randint`
## Декоратор, который будет ограничивать количество вызовов функций.
![изображение](https://github.com/Hasper1337/4laba/assets/145243810/d83e4241-ab90-41f4-be1a-14e51232661f)
`limit_calls(max_calls=1)`: Это внешняя функция, которая принимает один аргумент - максимальное количество вызовов функции. По умолчанию это значение равно 1. `calls = 0`: Это переменная, которая отслеживает количество вызовов декорируемой функции. `if calls >= max_calls`: Если количество вызовов функции достигло или превысило максимальное значение, то вызывается исключение.


`@limit_calls(3)`: Это декоратор, который применяется к функции `test_func`. Число 3 указывает, что функция `test_func` может быть вызвана не более 3 раз.`try: test_func()`: Здесь мы пытаемся вызвать функцию `test_func`. Если функция вызывается успешно, то она выводит строку "Вызов функции". Если количество вызовов функции превышает 3, то вызывается исключение. `except Exception as e: print(e)`: Если при вызове функции `test_func` возникает исключение, то оно перехватывается и выводится сообщение об ошибке.
